Workbook

Sheet Leia-me
A1: Planilha de precificação – versão corrigida (mesmas fórmulas do sistema)
A3: O que estava errado nas planilhas anteriores
A4: • Lucro, IR e cartão eram somados "por fora" do custo: lucro de 30% virava ~20% do preço e o IR de 15% virava ~13%.
A5: Agora todos os percentuais incidem sobre o PREÇO: preço = custo direto ÷ (1 − cartão − comissão − taxas − IR − lucro).
A6: • A comissão de 7% nunca era calculada (coluna vazia) e na aba HOF virava R$ 50/hora. O cartão só existia em 3 abas.
A7: • Cabeçalhos diziam "lucro 20%" com fórmula de 30%; havia células #REF!; implantes com material R$ 7 e sem horas.
A8: • O custo da estrutura por hora assumia 100% de ocupação (R$ 30,36/h). Com a ocupação como parâmetro (65%) dá R$ 46,71/h.
A9: • Materiais eram só listas de nomes. Agora cada material tem preço da embalagem, rendimento e perda; o custo entra pela quantidade usada.
A11: Como usar
A12: 1) Aba Parâmetros: despesas (o custo mensal sai sozinho), salas/horas/ocupação, hora clínica, cartão, comissão, lucro, regime de IR e taxas adicionais.
A13: 2) Aba Materiais: preço da embalagem, rendimento (quantas unidades de uso) e % de perda → custo por unidade de uso.
A14: 3) Aba Itens: materiais e quantidades de cada procedimento (o nome do procedimento tem que ser igual ao da aba Procedimentos).
... A26: Fonte: planilhas da clínica (despesas e procedimentos) e modelo de precificação; percentuais de IR são sugestões, valide com o contador.

Sheet Parâmetros
A1: Parâmetros da clínica
A3: Despesa | B3: Tipo | C3: Valor (R$)
A4: Telefone e internet | B4: Fixa mensal | C4: 149.9
A5: Salário recepção | B5: Fixa mensal | C5: 2500
A6: FGTS | B6: Fixa mensal | C6: 179
A7: Sanepar | B7: Fixa mensal | C7: 170
A8: Copel | B8: Fixa mensal | C8: 700
A9: BioAccess | B9: Fixa mensal | C9: 145
A10: Contabilidade | B10: Fixa mensal | C10: 165
A11: GPS | B11: Fixa mensal | C11: 850
A12: Diarista | B12: Fixa mensal | C12: 600
A13: Sistema | B13: Fixa mensal | C13: 300
A14: Aluguel | B14: Fixa mensal | C14: 3700
A15: Produtos de limpeza | B15: Variável mensal | C15: 200
... A32: Decoração | B32: Publicidade mensal | C32: 200
A44: Resumo do custo mensal
A45: Fixas mensais | B45: =SUMIF($B$4:$B$42,"Fixa mensal",$C$4:$C$42)
A46: Variáveis mensais | B46: =SUMIF($B$4:$B$42,"Variável mensal",$C$4:$C$42)
A47: Eventuais anuais ÷ 12 | B47: =SUMIF($B$4:$B$42,"Eventual anual",$C$4:$C$42)/12
A48: Publicidade mensal | B48: =SUMIF($B$4:$B$42,"Publicidade mensal",$C$4:$C$42)
A49: CUSTO MENSAL DA CLÍNICA | B49: =SUM(B45:B48)
A51: Estrutura e horas
A52: Salas (cadeiras) em uso | B52: 4
A53: Horas por semana, por sala | B53: 35
A54: Semanas por mês | B54: 4 | E54: 4,33 = 52 ÷ 12 se preferir a média
A55: Ocupação da agenda | B55: 0.65 | E55: Parte das horas abertas que realmente vira atendimento
A56: Horas produtivas por mês | B56: =B52*B53*B54*B55
A57: CUSTO DA ESTRUTURA POR HORA | B57: =IF(B56=0,0,B49/B56)
A59: Profissional e percentuais sobre o preço
A60: Hora clínica do profissional (R$/h) | B60: 50 | E60: Remuneração do dentista por hora de cadeira
A61: Taxa da máquina de cartão | B61: 0.04 | E61: Média de débito, crédito e parcelado
A62: Comissão (padrão) | B62: 0.07 | E62: Cada procedimento pode ter a sua (aba Procedimentos)
A63: Lucro desejado (padrão) | B63: 0.3
A64: Regime do IR (1 = pessoa física, 2 = pessoa jurídica) | B64: 2 | E64: PF: IR incide sobre o lucro (carnê-leão). PJ: tributos incidem sobre o faturamento (Simples / Presumido)
A65: IR pessoa física | B65: 0.275 | E65: Alíquota efetiva da sua faixa (teto 27,5%)
A66: Tributos pessoa jurídica | B66: 0.15 | E66: Simples 6% a 15,5%; Presumido 11,33% + ISS. Valide com o contador
A67: IR usado no preço | B67: =IF(B64=2,B66,B65)
A69: Taxas adicionais sobre o preço (1 = ativa, 0 = desligada)
A70: Taxa | B70: Percentual | C70: Ativa (1/0) | E70: Quando usar
A71: ISS | B71: 0.05 | C71: 0 | E71: Imposto municipal sobre serviços (2% a 5%). No Simples Nacional já está no DAS: deixe 0.
...

Sheet Materiais
A1: Material | B1: Embalagem | C1: Preço da embalagem (R$) | D1: Rendimento (unidades de uso) | E1: Unidade de uso | F1: Perda | G1: Custo por unidade de uso (R$)
A2: Resina composta A2 | B2: Seringa 4 g | C2: 89.9 | D2: 40 | E2: 0,1 g | F2: 0.1 | G2: =IF(OR(A2="",D2=0),0,C2/(D2*(1-F2)))
A3: Sistema adesivo | B3: Frasco 5 ml | C3: 120 | D3: 100 | E3: aplicação | F3: 0.1 | G3: =IF(OR(A3="",D3=0),0,C3/(D3*(1-F3)))
A4: Ácido fosfórico 37% | B4: Seringa 3 ml | C4: 12 | D4: 30 | E4: aplicação | F4: 0.1 | G4: =IF(OR(A4="",D4=0),0,C4/(D4*(1-F4)))
A5: Anestésico (tubete) | B5: Caixa 50 tubetes | C5: 95 | D5: 50 | E5: tubete | F5: 0 | G5: =IF(OR(A5="",D5=0),0,C5/(D5*(1-F5)))
A6: Agulha gengival curta | B6: Caixa 100 | C6: 45 | D6: 100 | E6: unidade | F6: 0 | G6: =IF(OR(A6="",D6=0),0,C6/(D6*(1-F6)))
A7: Luvas de procedimento | B7: Caixa 100 | C7: 38 | D7: 100 | E7: unidade | F7: 0 | G7: =IF(OR(A7="",D7=0),0,C7/(D7*(1-F7)))
A8: Máscara descartável | B8: Caixa 50 | C8: 22 | D8: 50 | E8: unidade | F8: 0 | G8: =IF(OR(A8="",D8=0),0,C8/(D8*(1-F8)))
A9: Babador descartável | B9: Pacote 100 | C9: 28 | D9: 100 | E9: unidade | F9: 0 | G9: =IF(OR(A9="",D9=0),0,C9/(D9*(1-F9)))
A10: Sugador descartável | B10: Pacote 40 | C10: 14 | D10: 40 | E10: unidade | F10: 0 | G10: =IF(OR(A10="",D10=0),0,C10/(D10*(1-F10)))
A11: Pasta profilática | B11: Pote 90 g | C11: 18 | D11: 90 | E11: 1 g | F11: 0.15 | G11: =IF(OR(A11="",D11=0),0,C11/(D11*(1-F11)))
A12: Gaze | B12: Pacote 500 | C12: 20 | D12: 500 | E12: unidade | F12: 0 | G12: =IF(OR(A12="",D12=0),0,C12/(D12*(1-F12)))
G13: =IF(OR(A13="",D13=0),0,C13/(D13*(1-F13)))
G14: =IF(OR(A14="",D14=0),0,C14/(D14*(1-F14)))
G15: =IF(OR(A15="",D15=0),0,C15/(D15*(1-F15)))
G16: =IF(OR(A16="",D16=0),0,C16/(D16*(1-F16)))
G17: =IF(OR(A17="",D17=0),0,C17/(D17*(1-F17)))
G18: =IF(OR(A18="",D18=0),0,C18/(D18*(1-F18)))
G19: =IF(OR(A19="",D19=0),0,C19/(D19*(1-F19)))
G20: =IF(OR(A20="",D20=0),0,C20/(D20*(1-F20)))
G21: =IF(OR(A21="",D21=0),0,C21/(D21*(1-F21)))
G22: =IF(OR(A22="",D22=0),0,C22/(D22*(1-F22)))
G23: =IF(OR(A23="",D23=0),0,C23/(D23*(1-F23)))
G24: =IF(OR(A24="",D24=0),0,C24/(D24*(1-F24)))
... G52: =IF(OR(A52="",D52=0),0,C52/(D52*(1-F52)))
A54: Valores de exemplo (fictícios): substitua pelos preços reais ou use a pesquisa de mercado do sistema.

Sheet Itens
A1: Procedimento | B1: Material | C1: Quantidade (unidades de uso) | D1: Custo unitário (R$) | E1: Custo da linha (R$)
A2: Profilaxia | B2: Pasta profilática | C2: 3 | D2: =IF(B2="",0,IFERROR(INDEX(Materiais!$G$2:$G$52,MATCH(B2,Materiais!$A$2:$A$52,0)),0)) | E2: =IF(B2="",0,C2*D2)
A3: Profilaxia | B3: Luvas de procedimento | C3: 2 | D3: =IF(B3="",0,IFERROR(INDEX(Materiais!$G$2:$G$52,MATCH(B3,Materiais!$A$2:$A$52,0)),0)) | E3: =IF(B3="",0,C3*D3)
A4: Profilaxia | B4: Sugador descartável | C4: 1 | D4: =IF(B4="",0,IFERROR(INDEX(Materiais!$G$2:$G$52,MATCH(B4,Materiais!$A$2:$A$52,0)),0)) | E4: =IF(B4="",0,C4*D4)
A5: Restauração simples 1 face | B5: Resina composta A2 | C5: 2 | D5: =IF(B5="",0,IFERROR(INDEX(Materiais!$G$2:$G$52,MATCH(B5,Materiais!$A$2:$A$52,0)),0)) | E5: =IF(B5="",0,C5*D5)
A6: Restauração simples 1 face | B6: Sistema adesivo | C6: 1 | D6: =IF(B6="",0,IFERROR(INDEX(Materiais!$G$2:$G$52,MATCH(B6,Materiais!$A$2:$A$52,0)),0)) | E6: =IF(B6="",0,C6*D6)
A7: Restauração simples 1 face | B7: Anestésico (tubete) | C7: 1 | D7: =IF(B7="",0,IFERROR(INDEX(Materiais!$G$2:$G$52,MATCH(B7,Materiais!$A$2:$A$52,0)),0)) | E7: =IF(B7="",0,C7*D7)
A8: Restauração simples 1 face | B8: Luvas de procedimento | C8: 2 | D8: =IF(B8="",0,IFERROR(INDEX(Materiais!$G$2:$G$52,MATCH(B8,Materiais!$A$2:$A$52,0)),0)) | E8: =IF(B8="",0,C8*D8)
D9: =IF(B9="",0,IFERROR(INDEX(Materiais!$G$2:$G$52,MATCH(B9,Materiais!$A$2:$A$52,0)),0)) | E9: =IF(B9="",0,C9*D9)
D10: =IF(B10="",0,IFERROR(INDEX(Materiais!$G$2:$G$52,MATCH(B10,Materiais!$A$2:$A$52,0)),0)) | E10: =IF(B10="",0,C10*D10)
D11: =IF(B11="",0,IFERROR(INDEX(Materiais!$G$2:$G$52,MATCH(B11,Materiais!$A$2:$A$52,0)),0)) | E11: =IF(B11="",0,C11*D11)
D12: =IF(B12="",0,IFERROR(INDEX(Materiais!$G$2:$G$52,MATCH(B12,Materiais!$A$2:$A$52,0)),0)) | E12: =IF(B12="",0,C12*D12)
D13: =IF(B13="",0,IFERROR(INDEX(Materiais!$G$2:$G$52,MATCH(B13,Materiais!$A$2:$A$52,0)),0)) | E13: =IF(B13="",0,C13*D13)
D14: =IF(B14="",0,IFERROR(INDEX(Materiais!$G$2:$G$52,MATCH(B14,Materiais!$A$2:$A$52,0)),0)) | E14: =IF(B14="",0,C14*D14)
D15: =IF(B15="",0,IFERROR(INDEX(Materiais!$G$2:$G$52,MATCH(B15,Materiais!$A$2:$A$52,0)),0)) | E15: =IF(B15="",0,C15*D15)
D16: =IF(B16="",0,IFERROR(INDEX(Materiais!$G$2:$G$52,MATCH(B16,Materiais!$A$2:$A$52,0)),0)) | E16: =IF(B16="",0,C16*D16)
D17: =IF(B17="",0,IFERROR(INDEX(Materiais!$G$2:$G$52,MATCH(B17,Materiais!$A$2:$A$52,0)),0)) | E17: =IF(B17="",0,C17*D17)
D18: =IF(B18="",0,IFERROR(INDEX(Materiais!$G$2:$G$52,MATCH(B18,Materiais!$A$2:$A$52,0)),0)) | E18: =IF(B18="",0,C18*D18)
D19: =IF(B19="",0,IFERROR(INDEX(Materiais!$G$2:$G$52,MATCH(B19,Materiais!$A$2:$A$52,0)),0)) | E19: =IF(B19="",0,C19*D19)
D20: =IF(B20="",0,IFERROR(INDEX(Materiais!$G$2:$G$52,MATCH(B20,Materiais!$A$2:$A$52,0)),0)) | E20: =IF(B20="",0,C20*D20)
... D158: =IF(B158="",0,IFERROR(INDEX(Materiais!$G$2:$G$52,MATCH(B158,Materiais!$A$2:$A$52,0)),0)) | E158: =IF(B158="",0,C158*D158)

Sheet Procedimentos
A1: Código | B1: Procedimento | C1: Categoria | D1: Tempo (min) | E1: Laboratório / terceiros (R$) | F1: Outros materiais (R$) | G1: Valor cobrado hoje (R$) | H1: Comissão própria (vazio = padrão) | I1: Lucro próprio (vazio = padrão) | J1: Materiais (R$) | K1: Estrutura (R$) | L1: Hora clínica (R$) | M1: CUSTO DIRETO (R$) | N1: Comissão usada | O1: Lucro usado | P1: Preço PJ (R$) | Q1: Preço PF (R$) | R1: PREÇO SUGERIDO (regime escolhido) | S1: Preço mínimo (lucro zero) | T1: Cartão (R$) | U1: Comissão (R$) | V1: Taxas (R$) | W1: IR (R$) | X1: Lucro (R$) | Y1: Lucro real (%) | Z1: Sugerido − atual (R$) | AA1: Alerta
A2: 1.0 | B2: Profilaxia | C2: Clínica Geral | D2: 60 | E2: 0 | F2: 2 | G2: 150 | J2: =IF($B2="","",SUMIFS(Itens!$E$2:$E$158,Itens!$A$2:$A$158,$B2)+N(F2)) | K2: =IF($B2="","",N(D2)/60*Parâmetros!$B$57) | L2: =IF($B2="","",N(D2)/60*Parâmetros!$B$60) | M2: =IF($B2="","",J2+N(E2)+K2+L2) | N2: =IF($B2="","",IF(H2="",Parâmetros!$B$62,H2)) | O2: =IF($B2="","",IF(I2="",Parâmetros!$B$63,I2)) | P2: =IF($B2="","",IF(1-(Parâmetros!$B$61+N2+Parâmetros!$B$78)-Parâmetros!$B$66-O2<=0,"ERRO",M2/(1-(Parâmetros!$B$61+N2+Parâmetros!$B$78)-Parâmetros!$B$66-O2))) | Q2: =IF($B2="","",IF((1-Parâmetros!$B$65)*(1-(Parâmetros!$B$61+N2+Parâmetros!$B$78))-O2<=0,"ERRO",(1-Parâmetros!$B$65)*M2/((1-Parâmetros!$B$65)*(1-(Parâmetros!$B$61+N2+Parâmetros!$B$78))-O2))) | R2: =IF($B2="","",IF(Parâmetros!$B$64=2,P2,Q2)) | S2: =IF($B2="","",IF(Parâmetros!$B$64=2,IF(1-(Parâmetros!$B$61+N2+Parâmetros!$B$78)-Parâmetros!$B$66<=0,"ERRO",M2/(1-(Parâmetros!$B$61+N2+Parâmetros!$B$78)-Parâmetros!$B$66)),IF((1-Parâmetros!$B$65)*(1-(Parâmetros!$B$61+N2+Parâmetros!$B$78))<=0,"ERRO",(1-Parâmetros!$B$65)*M2/((1-Parâmetros!$B$65)*(1-(Parâmetros!$B$61+N2+Parâmetros!$B$78)))))) | T2: =IF($B2="","",IF(ISNUMBER(R2),R2*Parâmetros!$B$61,"")) | U2: =IF($B2="","",IF(ISNUMBER(R2),R2*N2,"")) | V2: =IF($B2="","",IF(ISNUMBER(R2),R2*Parâmetros!$B$78,"")) | W2: =IF($B2="","",IF(ISNUMBER(R2),IF(Parâmetros!$B$64=2,R2*Parâmetros!$B$66,Parâmetros!$B$65*(R2-M2-R2*(Parâmetros!$B$61+N2+Parâmetros!$B$78))),"")) | X2: =IF($B2="","",IF(ISNUMBER(R2),R2-M2-T2-U2-V2-W2,"")) | Y2: =IF($B2="","",IF(AND(ISNUMBER(R2),R2>0),X2/R2,"")) | Z2: =IF($B2="","",IF(AND(ISNUMBER(R2),ISNUMBER(G2)),R2-G2,"")) | AA2: =IF($B2="","",IF(NOT(ISNUMBER(R2)),"Percentuais ≥ 100%",IF(N(D2)=0,"Sem tempo",IF(J2=0,"Sem materiais",""))))
A3: 2.0 | B3: Clareamento laser (1 sessão) | C3: Clínica Geral | D3: 90 | E3: 0 | F3: 63 | G3: 700 | J3: =IF($B3="","",SUMIFS(Itens!$E$2:$E$158,Itens!$A$2:$A$158,$B3)+N(F3)) | K3: =IF($B3="","",N(D3)/60*Parâmetros!$B$57) | L3: =IF($B3="","",N(D3)/60*Parâmetros!$B$60) | M3: =IF($B3="","",J3+N(E3)+K3+L3) | N3: =IF($B3="","",IF(H3="",Parâmetros!$B$62,H3)) | O3: =IF($B3="","",IF(I3="",Parâmetros!$B$63,I3)) | P3: =IF($B3="","",IF(1-(Parâmetros!$B$61+N3+Parâmetros!$B$78)-Parâmetros!$B$66-O3<=0,"ERRO",M3/(1-(Parâmetros!$B$61+N3+Parâmetros!$B$78)-Parâmetros!$B$66-O3))) | Q3: =IF($B3="","",IF((1-Parâmetros!$B$65)*(1-(Parâmetros!$B$61+N3+Parâmetros!$B$78))-O3<=0,"ERRO",(1-Parâmetros!$B$65)*M3/((1-Parâmetros!$B$65)*(1-(Parâmetros!$B$61+N3+Parâmetros!$B$78))-O3))) | R3: =IF($B3="","",IF(Parâmetros!$B$64=2,P3,Q3)) | S3: =IF($B3="","",IF(Parâmetros!$B$64=2,IF(1-(Parâmetros!$B$61+N3+Parâmetros!$B$78)-Parâmetros!$B$66<=0,"ERRO",M3/(1-(Parâmetros!$B$61+N3+Parâmetros!$B$78)-Parâmetros!$B$66)),IF((1-Parâmetros!$B$65)*(1-(Parâmetros!$B$61+N3+Parâmetros!$B$78))<=0,"ERRO",(1-Parâmetros!$B$65)*M3/((1-Parâmetros!$B$65)*(1-(Parâmetros!$B$61+N3+Parâmetros!$B$78)))))) | T3: =IF($B3="","",IF(ISNUMBER(R3),R3*Parâmetros!$B$61,"")) | U3: =IF($B3="","",IF(ISNUMBER(R3),R3*N3,"")) | V3: =IF($B3="","",IF(ISNUMBER(R3),R3*Parâmetros!$B$78,"")) | W3: =IF($B3="","",IF(ISNUMBER(R3),IF(Parâmetros!$B$64=2,R3*Parâmetros!$B$66,Parâmetros!$B$65*(R3-M3-R3*(Parâmetros!$B$61+N3+Parâmetros!$B$78))),"")) | X3: =IF($B3="","",IF(ISNUMBER(R3),R3-M3-T3-U3-V3-W3,"")) | Y3: =IF($B3="","",IF(AND(ISNUMBER(R3),R3>0),X3/R3,"")) | Z3: =IF($B3="","",IF(AND(ISNUMBER(R3),ISNUMBER(G3)),R3-G3,"")) | AA3: =IF($B3="","",IF(NOT(ISNUMBER(R3)),"Percentuais ≥ 100%",IF(N(D3)=0,"Sem tempo",IF(J3=0,"Sem materiais",""))))
A4: 2.1 | B4: Clareamento laser (2 sessões) | C4: Clínica Geral | D4: 180 | E4: 0 | F4: 126 | G4: 1200 | J4: =IF($B4="","",SUMIFS(Itens!$E$2:$E$158,Itens!$A$2:$A$158,$B4)+N(F4)) | K4: =IF($B4="","",N(D4)/60*Parâmetros!$B$57) | L4: =IF($B4="","",N(D4)/60*Parâmetros!$B$60) | M4: =IF($B4="","",J4+N(E4)+K4+L4) | N4: =IF($B4="","",IF(H4="",Parâmetros!$B$62,H4)) | O4: =IF($B4="","",IF(I4="",Parâmetros!$B$63,I4)) | P4: =IF($B4="","",IF(1-(Parâmetros!$B$61+N4+Parâmetros!$B$78)-Parâmetros!$B$66-O4<=0,"ERRO",M4/(1-(Parâmetros!$B$61+N4+Parâmetros!$B$78)-Parâmetros!$B$66-O4))) | Q4: =IF($B4="","",IF((1-Parâmetros!$B$65)*(1-(Parâmetros!$B$61+N4+Parâmetros!$B$78))-O4<=0,"ERRO",(1-Parâmetros!$B$65)*M4/((1-Parâmetros!$B$65)*(1-(Parâmetros!$B$61+N4+Parâmetros!$B$78))-O4))) | R4: =IF($B4="","",IF(Parâmetros!$B$64=2,P4,Q4)) | S4: =IF($B4="","",IF(Parâmetros!$B$64=2,IF(1-(Parâmetros!$B$61+N4+Parâmetros!$B$78)-Parâmetros!$B$66<=0,"ERRO",M4/(1-(Parâmetros!$B$61+N4+Parâmetros!$B$78)-Parâmetros!$B$66)),IF((1-Parâmetros!$B$65)*(1-(Parâmetros!$B$61+N4+Parâmetros!$B$78))<=0,"ERRO",(1-Parâmetros!$B$65)*M4/((1-Parâmetros!$B$65)*(1-(Parâmetros!$B$61+N4+Parâmetros!$B$78)))))) | T4: =IF($B4="","",IF(ISNUMBER(R4),R4*Parâmetros!$B$61,"")) | U4: =IF($B4="","",IF(ISNUMBER(R4),R4*N4,"")) | V4: =IF($B4="","",IF(ISNUMBER(R4),R4*Parâmetros!$B$78,"")) | W4: =IF($B4="","",IF(ISNUMBER(R4),IF(Parâmetros!$B$64=2,R4*Parâmetros!$B$66,Parâmetros!$B$65*(R4-M4-R4*(Parâmetros!$B$61+N4+Parâmetros!$B$78))),"")) | X4: =IF($B4="","",IF(ISNUMBER(R4),R4-M4-T4-U4-V4-W4,"")) | Y4: =IF($B4="","",IF(AND(ISNUMBER(R4),R4>0),X4/R4,"")) | Z4: =IF($B4="","",IF(AND(ISNUMBER(R4),ISNUMBER(G4)),R4-G4,"")) | AA4: =IF($B4="","",IF(NOT(ISNUMBER(R4)),"Percentuais ≥ 100%",IF(N(D4)=0,"Sem tempo",IF(J4=0,"Sem materiais",""))))
A5: 2.2 | B5: Clareamento laser (sessão avulsa) | C5: Clínica Geral | D5: 90 | E5: 0 | F5: 63 | G5: 700 | J5: =IF($B5="","",SUMIFS(Itens!$E$2:$E$158,Itens!$A$2:$A$158,$B5)+N(F5)) | K5: =IF($B5="","",N(D5)/60*Parâmetros!$B$57) | L5: =IF($B5="","",N(D5)/60*Parâmetros!$B$60) | M5: =IF($B5="","",J5+N(E5)+K5+L5) | N5: =IF($B5="","",IF(H5="",Parâmetros!$B$62,H5)) | O5: =IF($B5="","",IF(I5="",Parâmetros!$B$63,I5)) | P5: =IF($B5="","",IF(1-(Parâmetros!$B$61+N5+Parâmetros!$B$78)-Parâmetros!$B$66-O5<=0,"ERRO",M5/(1-(Parâmetros!$B$61+N5+Parâmetros!$B$78)-Parâmetros!$B$66-O5))) | Q5: =IF($B5="","",IF((1-Parâmetros!$B$65)*(1-(Parâmetros!$B$61+N5+Parâmetros!$B$78))-O5<=0,"ERRO",(1-Parâmetros!$B$65)*M5/((1-Parâmetros!$B$65)*(1-(Parâmetros!$B$61+N5+Parâmetros!$B$78))-O5))) | R5: =IF($B5="","",IF(Parâmetros!$B$64=2,P5,Q5)) | S5: =IF($B5="","",IF(Parâmetros!$B$64=2,IF(1-(Parâmetros!$B$61+N5+Parâmetros!$B$78)-Parâmetros!$B$66<=0,"ERRO",M5/(1-(Parâmetros!$B$61+N5+Parâmetros!$B$78)-Parâmetros!$B$66)),IF((1-Parâmetros!$B$65)*(1-(Parâmetros!$B$61+N5+Parâmetros!$B$78))<=0,"ERRO",(1-Parâmetros!$B$65)*M5/((1-Parâmetros!$B$65)*(1-(Parâmetros!$B$61+N5+Parâmetros!$B$78)))))) | T5: =IF($B5="","",IF(ISNUMBER(R5),R5*Parâmetros!$B$61,"")) | U5: =IF($B5="","",IF(ISNUMBER(R5),R5*N5,"")) | V5: =IF($B5="","",IF(ISNUMBER(R5),R5*Parâmetros!$B$78,"")) | W5: =IF($B5="","",IF(ISNUMBER(R5),IF(Parâmetros!$B$64=2,R5*Parâmetros!$B$66,Parâmetros!$B$65*(R5-M5-R5*(Parâmetros!$B$61+N5+Parâmetros!$B$78))),"")) | X5: =IF($B5="","",IF(ISNUMBER(R5),R5-M5-T5-U5-V5-W5,"")) | Y5: =IF($B5="","",IF(AND(ISNUMBER(R5),R5>0),X5/R5,"")) | Z5: =IF($B5="","",IF(AND(ISNUMBER(R5),ISNUMBER(G5)),R5-G5,"")) | AA5: =IF($B5="","",IF(NOT(ISNUMBER(R5)),"Percentuais ≥ 100%",IF(N(D5)=0,"Sem tempo",IF(J5=0,"Sem materiais",""))))
A6: 2.3 | B6: Clareamento caseiro (2 seringas) | C6: Clínica Geral | D6: 60 | E6: 0 | F6: 70 | G6: 650 | J6: =IF($B6="","",SUMIFS(Itens!$E$2:$E$158,Itens!$A$2:$A$158,$B6)+N(F6)) | K6: =IF($B6="","",N(D6)/60*Parâmetros!$B$57) | L6: =IF($B6="","",N(D6)/60*Parâmetros!$B$60) | M6: =IF($B6="","",J6+N(E6)+K6+L6) | N6: =IF($B6="","",IF(H6="",Parâmetros!$B$62,H6)) | O6: =IF($B6="","",IF(I6="",Parâmetros!$B$63,I6)) | P6: =IF($B6="","",IF(1-(Parâmetros!$B$61+N6+Parâmetros!$B$78)-Parâmetros!$B$66-O6<=0,"ERRO",M6/(1-(Parâmetros!$B$61+N6+Parâmetros!$B$78)-Parâmetros!$B$66-O6))) | Q6: =IF($B6="","",IF((1-Parâmetros!$B$65)*(1-(Parâmetros!$B$61+N6+Parâmetros!$B$78))-O6<=0,"ERRO",(1-Parâmetros!$B$65)*M6/((1-Parâmetros!$B$65)*(1-(Parâmetros!$B$61+N6+Parâmetros!$B$78))-O6))) | R6: =IF($B6="","",IF(Parâmetros!$B$64=2,P6,Q6)) | S6: =IF($B6="","",IF(Parâmetros!$B$64=2,IF(1-(Parâmetros!$B$61+N6+Parâmetros!$B$78)-Parâmetros!$B$66<=0,"ERRO",M6/(1-(Parâmetros!$B$61+N6+Parâmetros!$B$78)-Parâmetros!$B$66)),IF((1-Parâmetros!$B$65)*(1-(Parâmetros!$B$61+N6+Parâmetros!$B$78))<=0,"ERRO",(1-Parâmetros!$B$65)*M6/((1-Parâmetros!$B$65)*(1-(Parâmetros!$B$61+N6+Parâmetros!$B$78)))))) | T6: =IF($B6="","",IF(ISNUMBER(R6),R6*Parâmetros!$B$61,"")) | U6: =IF($B6="","",IF(ISNUMBER(R6),R6*N6,"")) | V6: =IF($B6="","",IF(ISNUMBER(R6),R6*Parâmetros!$B$78,"")) | W6: =IF($B6="","",IF(ISNUMBER(R6),IF(Parâmetros!$B$64=2,R6*Parâmetros!$B$66,Parâmetros!$B$65*(R6-M6-R6*(Parâmetros!$B$61+N6+Parâmetros!$B$78))),"")) | X6: =IF($B6="","",IF(ISNUMBER(R6),R6-M6-T6-U6-V6-W6,"")) | Y6: =IF($B6="","",IF(AND(ISNUMBER(R6),R6>0),X6/R6,"")) | Z6: =IF($B6="","",IF(AND(ISNUMBER(R6),ISNUMBER(G6)),R6-G6,"")) | AA6: =IF($B6="","",IF(NOT(ISNUMBER(R6)),"Percentuais ≥ 100%",IF(N(D6)=0,"Sem tempo",IF(J6=0,"Sem materiais",""))))
A7: 2.4 | B7: Seringa avulsa clareador | C7: Clínica Geral | D7: 0 | E7: 0 | F7: 20 | G7: 350 | J7: =IF($B7="","",SUMIFS(Itens!$E$2:$E$158,Itens!$A$2:$A$158,$B7)+N(F7)) | K7: =IF($B7="","",N(D7)/60*Parâmetros!$B$57) | L7: =IF($B7="","",N(D7)/60*Parâmetros!$B$60) | M7: =IF($B7="","",J7+N(E7)+K7+L7) | N7: =IF($B7="","",IF(H7="",Parâmetros!$B$62,H7)) | O7: =IF($B7="","",IF(I7="",Parâmetros!$B$63,I7)) | P7: =IF($B7="","",IF(1-(Parâmetros!$B$61+N7+Parâmetros!$B$78)-Parâmetros!$B$66-O7<=0,"ERRO",M7/(1-(Parâmetros!$B$61+N7+Parâmetros!$B$78)-Parâmetros!$B$66-O7))) | Q7: =IF($B7="","",IF((1-Parâmetros!$B$65)*(1-(Parâmetros!$B$61+N7+Parâmetros!$B$78))-O7<=0,"ERRO",(1-Parâmetros!$B$65)*M7/((1-Parâmetros!$B$65)*(1-(Parâmetros!$B$61+N7+Parâmetros!$B$78))-O7))) | R7: =IF($B7="","",IF(Parâmetros!$B$64=2,P7,Q7)) | S7: =IF($B7="","",IF(Parâmetros!$B$64=2,IF(1-(Parâmetros!$B$61+N7+Parâmetros!$B$78)-Parâmetros!$B$66<=0,"ERRO",M7/(1-(Parâmetros!$B$61+N7+Parâmetros!$B$78)-Parâmetros!$B$66)),IF((1-Parâmetros!$B$65)*(1-(Parâmetros!$B$61+N7+Parâmetros!$B$78))<=0,"ERRO",(1-Parâmetros!$B$65)*M7/((1-Parâmetros!$B$65)*(1-(Parâmetros!$B$61+N7+Parâmetros!$B$78)))))) | T7: =IF($B7="","",IF(ISNUMBER(R7),R7*Parâmetros!$B$61,"")) | U7: =IF($B7="","",IF(ISNUMBER(R7),R7*N7,"")) | V7: =IF($B7="","",IF(ISNUMBER(R7),R7*Parâmetros!$B$78,"")) | W7: =IF($B7="","",IF(ISNUMBER(R7),IF(Parâmetros!$B$64=2,R7*Parâmetros!$B$66,Parâmetros!$B$65*(R7-M7-R7*(Parâmetros!$B$61+N7+Parâmetros!$B$78))),"")) | X7: =IF($B7="","",IF(ISNUMBER(R7),R7-M7-T7-U7-V7-W7,"")) | Y7: =IF($B7="","",IF(AND(ISNUMBER(R7),R7>0),X7/R7,"")) | Z7: =IF($B7="","",IF(AND(ISNUMBER(R7),ISNUMBER(G7)),R7-G7,"")) | AA7: =IF($B7="","",IF(NOT(ISNUMBER(R7)),"Percentuais ≥ 100%",IF(N(D7)=0,"Sem tempo",IF(J7=0,"Sem materiais",""))))
B8: Clareamento interno unitário | C8: Clínica Geral | D8: 90 | E8: 0 | F8: 20 | J8: =IF($B8="","",SUMIFS(Itens!$E$2:$E$158,Itens!$A$2:$A$158,$B8)+N(F8)) | K8: =IF($B8="","",N(D8)/60*Parâmetros!$B$57) | L8: =IF($B8="","",N(D8)/60*Parâmetros!$B$60) | M8: =IF($B8="","",J8+N(E8)+K8+L8) | N8: =IF($B8="","",IF(H8="",Parâmetros!$B$62,H8)) | O8: =IF($B8="","",IF(I8="",Parâmetros!$B$63,I8)) | P8: =IF($B8="","",IF(1-(Parâmetros!$B$61+N8+Parâmetros!$B$78)-Parâmetros!$B$66-O8<=0,"ERRO",M8/(1-(Parâmetros!$B$61+N8+Parâmetros!$B$78)-Parâmetros!$B$66-O8))) | Q8: =IF($B8="","",IF((1-Parâmetros!$B$65)*(1-(Parâmetros!$B$61+N8+Parâmetros!$B$78))-O8<=0,"ERRO",(1-Parâmetros!$B$65)*M8/((1-Parâmetros!$B$65)*(1-(Parâmetros!$B$61+N8+Parâmetros!$B$78))-O8))) | R8: =IF($B8="","",IF(Parâmetros!$B$64=2,P8,Q8)) | S8: =IF($B8="","",IF(Parâmetros!$B$64=2,IF(1-(Parâmetros!$B$61+N8+Parâmetros!$B$78)-Parâmetros!$B$66<=0,"ERRO",M8/(1-(Parâmetros!$B$61+N8+Parâmetros!$B$78)-Parâmetros!$B$66)),IF((1-Parâmetros!$B$65)*(1-(Parâmetros!$B$61+N8+Parâmetros!$B$78))<=0,"ERRO",(1-Parâmetros!$B$65)*M8/((1-Parâmetros!$B$65)*(1-(Parâmetros!$B$61+N8+Parâmetros!$B$78)))))) | T8: =IF($B8="","",IF(ISNUMBER(R8),R8*Parâmetros!$B$61,"")) | U8: =IF($B8="","",IF(ISNUMBER(R8),R8*N8,"")) | V8: =IF($B8="","",IF(ISNUMBER(R8),R8*Parâmetros!$B$78,"")) | W8: =IF($B8="","",IF(ISNUMBER(R8),IF(Parâmetros!$B$64=2,R8*Parâmetros!$B$66,Parâmetros!$B$65*(R8-M8-R8*(Parâmetros!$B$61+N8+Parâmetros!$B$78))),"")) | X8: =IF($B8="","",IF(ISNUMBER(R8),R8-M8-T8-U8-V8-W8,"")) | Y8: =IF($B8="","",IF(AND(ISNUMBER(R8),R8>0),X8/R8,"")) | Z8: =IF($B8="","",IF(AND(ISNUMBER(R8),ISNUMBER(G8)),R8-G8,"")) | AA8: =IF($B8="","",IF(NOT(ISNUMBER(R8)),"Percentuais ≥ 100%",IF(N(D8)=0,"Sem tempo",IF(J8=0,"Sem materiais",""))))
A9: 3.0 | B9: Restauração simples 1 face | C9: Clínica Geral | D9: 60 | E9: 0 | F9: 30 | J9: =IF($B9="","",SUMIFS(Itens!$E$2:$E$158,Itens!$A$2:$A$158,$B9)+N(F9)) | K9: =IF($B9="","",N(D9)/60*Parâmetros!$B$57) | L9: =IF($B9="","",N(D9)/60*Parâmetros!$B$60) | M9: =IF($B9="","",J9+N(E9)+K9+L9) | N9: =IF($B9="","",IF(H9="",Parâmetros!$B$62,H9)) | O9: =IF($B9="","",IF(I9="",Parâmetros!$B$63,I9)) | P9: =IF($B9="","",IF(1-(Parâmetros!$B$61+N9+Parâmetros!$B$78)-Parâmetros!$B$66-O9<=0,"ERRO",M9/(1-(Parâmetros!$B$61+N9+Parâmetros!$B$78)-Parâmetros!$B$66-O9))) | Q9: =IF($B9="","",IF((1-Parâmetros!$B$65)*(1-(Parâmetros!$B$61+N9+Parâmetros!$B$78))-O9<=0,"ERRO",(1-Parâmetros!$B$65)*M9/((1-Parâmetros!$B$65)*(1-(Parâmetros!$B$61+N9+Parâmetros!$B$78))-O9))) | R9: =IF($B9="","",IF(Parâmetros!$B$64=2,P9,Q9)) | S9: =IF($B9="","",IF(Parâmetros!$B$64=2,IF(1-(Parâmetros!$B$61+N9+Parâmetros!$B$78)-Parâmetros!$B$66<=0,"ERRO",M9/(1-(Parâmetros!$B$61+N9+Parâmetros!$B$78)-Parâmetros!$B$66)),IF((1-Parâmetros!$B$65)*(1-(Parâmetros!$B$61+N9+Parâmetros!$B$78))<=0,"ERRO",(1-Parâmetros!$B$65)*M9/((1-Parâmetros!$B$65)*(1-(Parâmetros!$B$61+N9+Parâmetros!$B$78)))))) | T9: =IF($B9="","",IF(ISNUMBER(R9),R9*Parâmetros!$B$61,"")) | U9: =IF($B9="","",IF(ISNUMBER(R9),R9*N9,"")) | V9: =IF($B9="","",IF(ISNUMBER(R9),R9*Parâmetros!$B$78,"")) | W9: =IF($B9="","",IF(ISNUMBER(R9),IF(Parâmetros!$B$64=2,R9*Parâmetros!$B$66,Parâmetros!$B$65*(R9-M9-R9*(Parâmetros!$B$61+N9+Parâmetros!$B$78))),"")) | X9: =IF($B9="","",IF(ISNUMBER(R9),R9-M9-T9-U9-V9-W9,"")) | Y9: =IF($B9="","",IF(AND(ISNUMBER(R9),R9>0),X9/R9,"")) | Z9: =IF($B9="","",IF(AND(ISNUMBER(R9),ISNUMBER(G9)),R9-G9,"")) | AA9: =IF($B9="","",IF(NOT(ISNUMBER(R9)),"Percentuais ≥ 100%",IF(N(D9)=0,"Sem tempo",IF(J9=0,"Sem materiais",""))))
A10: 3.1 | B10: Restauração simples 2 faces | C10: Clínica Geral | D10: 60 | E10: 0 | F10: 40 | J10: =IF($B10="","",SUMIFS(Itens!$E$2:$E$158,Itens!$A$2:$A$158,$B10)+N(F10)) | K10: =IF($B10="","",N(D10)/60*Parâmetros!$B$57) | L10: =IF($B10="","",N(D10)/60*Parâmetros!$B$60) | M10: =IF($B10="","",J10+N(E10)+K10+L10) | N10: =IF($B10="","",IF(H10="",Parâmetros!$B$62,H10)) | O10: =IF($B10="","",IF(I10="",Parâmetros!$B$63,I10)) | P10: =IF($B10="","",IF(1-(Parâmetros!$B$61+N10+Parâmetros!$B$78)-Parâmetros!$B$66-O10<=0,"ERRO",M10/(1-(Parâmetros!$B$61+N10+Parâmetros!$B$78)-Parâmetros!$B$66-O10))) | Q10: =IF($B10="","",IF((1-Parâmetros!$B$65)*(1-(Parâmetros!$B$61+N10+Parâmetros!$B$78))-O10<=0,"ERRO",(1-Parâmetros!$B$65)*M10/((1-Parâmetros!$B$65)*(1-(Parâmetros!$B$61+N10+Parâmetros!$B$78))-O10))) | R10: =IF($B10="","",IF(Parâmetros!$B$64=2,P10,Q10)) | S10: =IF($B10="","",IF(Parâmetros!$B$64=2,IF(1-(Parâmetros!$B$61+N10+Parâmetros!$B$78)-Parâmetros!$B$66<=0,"ERRO",M10/(1-(Parâmetros!$B$61+N10+Parâmetros!$B$78)-Parâmetros!$B$66)),IF((1-Parâmetros!$B$65)*(1-(Parâmetros!$B$61+N10+Parâmetros!$B$78))<=0,"ERRO",(1-Parâmetros!$B$65)*M10/((1-Parâmetros!$B$65)*(1-(Parâmetros!$B$61+N10+Parâmetros!$B$78)))))) | T10: =IF($B10="","",IF(ISNUMBER(R10),R10*Parâmetros!$B$61,"")) | U10: =IF($B10="","",IF(ISNUMBER(R10),R10*N10,"")) | V10: =IF($B10="","",IF(ISNUMBER(R10),R10*Parâmetros!$B$78,"")) | W10: =IF($B10="","",IF(ISNUMBER(R10),IF(Parâmetros!$B$64=2,R10*Parâmetros!$B$66,Parâmetros!$B$65*(R10-M10-R10*(Parâmetros!$B$61+N10+Parâmetros!$B$78))),"")) | X10: =IF($B10="","",IF(ISNUMBER(R10),R10-M10-T10-U10-V10-W10,"")) | Y10: =IF($B10="","",IF(AND(ISNUMBER(R10),R10>0),X10/R10,"")) | Z10: =IF($B10="","",IF(AND(ISNUMBER(R10),ISNUMBER(G10)),R10-G10,"")) | AA10: =IF($B10="","",IF(NOT(ISNUMBER(R10)),"Percentuais ≥ 100%",IF(N(D10)=0,"Sem tempo",IF(J10=0,"Sem materiais",""))))
A11: 3.2 | B11: Restauração simples 3 faces | C11: Clínica Geral | D11: 60 | E11: 0 | F11: 50 | J11: =IF($B11="","",SUMIFS(Itens!$E$2:$E$158,Itens!$A$2:$A$158,$B11)+N(F11)) | K11: =IF($B11="","",N(D11)/60*Parâmetros!$B$57) | L11: =IF($B11="","",N(D11)/60*Parâmetros!$B$60) | M11: =IF($B11="","",J11+N(E11)+K11+L11) | N11: =IF($B11="","",IF(H11="",Parâmetros!$B$62,H11)) | O11: =IF($B11="","",IF(I11="",Parâmetros!$B$63,I11)) | P11: =IF($B11="","",IF(1-(Parâmetros!$B$61+N11+Parâmetros!$B$78)-Parâmetros!$B$66-O11<=0,"ERRO",M11/(1-(Parâmetros!$B$61+N11+Parâmetros!$B$78)-Parâmetros!$B$66-O11))) | Q11: =IF($B11="","",IF((1-Parâmetros!$B$65)*(1-(Parâmetros!$B$61+N11+Parâmetros!$B$78))-O11<=0,"ERRO",(1-Parâmetros!$B$65)*M11/((1-Parâmetros!$B$65)*(1-(Parâmetros!$B$61+N11+Parâmetros!$B$78))-O11))) | R11: =IF($B11="","",IF(Parâmetros!$B$64=2,P11,Q11)) | S11: =IF($B11="","",IF(Parâmetros!$B$64=2,IF(1-(Parâmetros!$B$61+N11+Parâmetros!$B$78)-Parâmetros!$B$66<=0,"ERRO",M11/(1-(Parâmetros!$B$61+N11+Parâmetros!$B$78)-Parâmetros!$B$66)),IF((1-Parâmetros!$B$65)*(1-(Parâmetros!$B$61+N11+Parâmetros!$B$78))<=0,"ERRO",(1-Parâmetros!$B$65)*M11/((1-Parâmetros!$B$65)*(1-(Parâmetros!$B$61+N11+Parâmetros!$B$78)))))) | T11: =IF($B11="","",IF(ISNUMBER(R11),R11*Parâmetros!$B$61,"")) | U11: =IF($B11="","",IF(ISNUMBER(R11),R11*N11,"")) | V11: =IF($B11="","",IF(ISNUMBER(R11),R11*Parâmetros!$B$78,"")) | W11: =IF($B11="","",IF(ISNUMBER(R11),IF(Parâmetros!$B$64=2,R11*Parâmetros!$B$66,Parâmetros!$B$65*(R11-M11-R11*(Parâmetros!$B$61+N11+Parâmetros!$B$78))),"")) | X11: =IF($B11="","",IF(ISNUMBER(R11),R11-M11-T11-U11-V11-W11,"")) | Y11: =IF($B11="","",IF(AND(ISNUMBER(R11),R11>0),X11/R11,"")) | Z11: =IF($B11="","",IF(AND(ISNUMBER(R11),ISNUMBER(G11)),R11-G11,"")) | AA11: =IF($B11="","",IF(NOT(ISNUMBER(R11)),"Percentuais ≥ 100%",IF(N(D11)=0,"Sem tempo",IF(J11=0,"Sem materiais",""))))
A12: 3.3 | B12: Restauração em resina com pino fibra de vidro | C12: Clínica Geral | D12: 120 | E12: 0 | F12: 150 | J12: =IF($B12="","",SUMIFS(Itens!$E$2:$E$158,Itens!$A$2:$A$158,$B12)+N(F12)) | K12: =IF($B12="","",N(D12)/60*Parâmetros!$B$57) | L12: =IF($B12="","",N(D12)/60*Parâmetros!$B$60) | M12: =IF($B12="","",J12+N(E12)+K12+L12) | N12: =IF($B12="","",IF(H12="",Parâmetros!$B$62,H12)) | O12: =IF($B12="","",IF(I12="",Parâmetros!$B$63,I12)) | P12: =IF($B12="","",IF(1-(Parâmetros!$B$61+N12+Parâmetros!$B$78)-Parâmetros!$B$66-O12<=0,"ERRO",M12/(1-(Parâmetros!$B$61+N12+Parâmetros!$B$78)-Parâmetros!$B$66-O12))) | Q12: =IF($B12="","",IF((1-Parâmetros!$B$65)*(1-(Parâmetros!$B$61+N12+Parâmetros!$B$78))-O12<=0,"ERRO",(1-Parâmetros!$B$65)*M12/((1-Parâmetros!$B$65)*(1-(Parâmetros!$B$61+N12+Parâmetros!$B$78))-O12))) | R12: =IF($B12="","",IF(Parâmetros!$B$64=2,P12,Q12)) | S12: =IF($B12="","",IF(Parâmetros!$B$64=2,IF(1-(Parâmetros!$B$61+N12+Parâmetros!$B$78)-Parâmetros!$B$66<=0,"ERRO",M12/(1-(Parâmetros!$B$61+N12+Parâmetros!$B$78)-Parâmetros!$B$66)),IF((1-Parâmetros!$B$65)*(1-(Parâmetros!$B$61+N12+Parâmetros!$B$78))<=0,"ERRO",(1-Parâmetros!$B$65)*M12/((1-Parâmetros!$B$65)*(1-(Parâmetros!$B$61+N12+Parâmetros!$B$78)))))) | T12: =IF($B12="","",IF(ISNUMBER(R12),R12*Parâmetros!$B$61,"")) | U12: =IF($B12="","",IF(ISNUMBER(R12),R12*N12,"")) | V12: =IF($B12="","",IF(ISNUMBER(R12),R12*Parâmetros!$B$78,"")) | W12: =IF($B12="","",IF(ISNUMBER(R12),IF(Parâmetros!$B$64=2,R12*Parâmetros!$B$66,Parâmetros!$B$65*(R12-M12-R12*(Parâmetros!$B$61+N12+Parâmetros!$B$78))),"")) | X12: =IF($B12="","",IF(ISNUMBER(R12),R12-M12-T12-U12-V12-W12,"")) | Y12: =IF($B12="","",IF(AND(ISNUMBER(R12),R12>0),X12/R12,"")) | Z12: =IF($B12="","",IF(AND(ISNUMBER(R12),ISNUMBER(G12)),R12-G12,"")) | AA12: =IF($B12="","",IF(NOT(ISNUMBER(R12)),"Percentuais ≥ 100%",IF(N(D12)=0,"Sem tempo",IF(J12=0,"Sem materiais",""))))
A13: 3.4 | B13: Restauração estética / faceta | C13: Clínica Geral | D13: 120 | E13: 0 | F13: 34.49 | J13: =IF($B13="","",SUMIFS(Itens!$E$2:$E$158,Itens!$A$2:$A$158,$B13)+N(F13)) | K13: =IF($B13="","",N(D13)/60*Parâmetros!$B$57) | L13: =IF($B13="","",N(D13)/60*Parâmetros!$B$60) | M13: =IF($B13="","",J13+N(E13)+K13+L13) | N13: =IF($B13="","",IF(H13="",Parâmetros!$B$62,H13)) | O13: =IF($B13="","",IF(I13="",Parâmetros!$B$63,I13)) | P13: =IF($B13="","",IF(1-(Parâmetros!$B$61+N13+Parâmetros!$B$78)-Parâmetros!$B$66-O13<=0,"ERRO",M13/(1-(Parâmetros!$B$61+N13+Parâmetros!$B$78)-Parâmetros!$B$66-O13))) | Q13: =IF($B13="","",IF((1-Parâmetros!$B$65)*(1-(Parâmetros!$B$61+N13+Parâmetros!$B$78))-O13<=0,"ERRO",(1-Parâmetros!$B$65)*M13/((1-Parâmetros!$B$65)*(1-(Parâmetros!$B$61+N13+Parâmetros!$B$78))-O13))) | R13: =IF($B13="","",IF(Parâmetros!$B$64=2,P13,Q13)) | S13: =IF($B13="","",IF(Parâmetros!$B$64=2,IF(1-(Parâmetros!$B$61+N13+Parâmetros!$B$78)-Parâmetros!$B$66<=0,"ERRO",M13/(1-(Parâmetros!$B$61+N13+Parâmetros!$B$78)-Parâmetros!$B$66)),IF((1-Parâmetros!$B$65)*(1-(Parâmetros!$B$61+N13+Parâmetros!$B$78))<=0,"ERRO",(1-Parâmetros!$B$65)*M13/((1-Parâmetros!$B$65)*(1-(Parâmetros!$B$61+N13+Parâmetros!$B$78)))))) | T13: =IF($B13="","",IF(ISNUMBER(R13),R13*Parâmetros!$B$61,"")) | U13: =IF($B13="","",IF(ISNUMBER(R13),R13*N13,"")) | V13: =IF($B13="","",IF(ISNUMBER(R13),R13*Parâmetros!$B$78,"")) | W13: =IF($B13="","",IF(ISNUMBER(R13),IF(Parâmetros!$B$64=2,R13*Parâmetros!$B$66,Parâmetros!$B$65*(R13-M13-R13*(Parâmetros!$B$61+N13+Parâmetros!$B$78))),"")) | X13: =IF($B13="","",IF(ISNUMBER(R13),R13-M13-T13-U13-V13-W13,"")) | Y13: =IF($B13="","",IF(AND(ISNUMBER(R13),R13>0),X13/R13,"")) | Z13: =IF($B13="","",IF(AND(ISNUMBER(R13),ISNUMBER(G13)),R13-G13,"")) | AA13: =IF($B13="","",IF(NOT(ISNUMBER(R13)),"Percentuais ≥ 100%",IF(N(D13)=0,"Sem tempo",IF(J13=0,"Sem materiais",""))))
A14: 3.5 | B14: Biobase | C14: Clínica Geral | D14: 120 | E14: 0 | F14: 45.25 | J14: =IF($B14="","",SUMIFS(Itens!$E$2:$E$158,Itens!$A$2:$A$158,$B14)+N(F14)) | K14: =IF($B14="","",N(D14)/60*Parâmetros!$B$57) | L14: =IF($B14="","",N(D14)/60*Parâmetros!$B$60) | M14: =IF($B14="","",J14+N(E14)+K14+L14) | N14: =IF($B14="","",IF(H14="",Parâmetros!$B$62,H14)) | O14: =IF($B14="","",IF(I14="",Parâmetros!$B$63,I14)) | P14: =IF($B14="","",IF(1-(Parâmetros!$B$61+N14+Parâmetros!$B$78)-Parâmetros!$B$66-O14<=0,"ERRO",M14/(1-(Parâmetros!$B$61+N14+Parâmetros!$B$78)-Parâmetros!$B$66-O14))) | Q14: =IF($B14="","",IF((1-Parâmetros!$B$65)*(1-(Parâmetros!$B$61+N14+Parâmetros!$B$78))-O14<=0,"ERRO",(1-Parâmetros!$B$65)*M14/((1-Parâmetros!$B$65)*(1-(Parâmetros!$B$61+N14+Parâmetros!$B$78))-O14))) | R14: =IF($B14="","",IF(Parâmetros!$B$64=2,P14,Q14)) | S14: =IF($B14="","",IF(Parâmetros!$B$64=2,IF(1-(Parâmetros!$B$61+N14+Parâmetros!$B$78)-Parâmetros!$B$66<=0,"ERRO",M14/(1-(Parâmetros!$B$61+N14+Parâmetros!$B$78)-Parâmetros!$B$66)),IF((1-Parâmetros!$B$65)*(1-(Parâmetros!$B$61+N14+Parâmetros!$B$78))<=0,"ERRO",(1-Parâmetros!$B$65)*M14/((1-Parâmetros!$B$65)*(1-(Parâmetros!$B$61+N14+Parâmetros!$B$78)))))) | T14: =IF($B14="","",IF(ISNUMBER(R14),R14*Parâmetros!$B$61,"")) | U14: =IF($B14="","",IF(ISNUMBER(R14),R14*N14,"")) | V14: =IF($B14="","",IF(ISNUMBER(R14),R14*Parâmetros!$B$78,"")) | W14: =IF($B14="","",IF(ISNUMBER(R14),IF(Parâmetros!$B$64=2,R14*Parâmetros!$B$66,Parâmetros!$B$65*(R14-M14-R14*(Parâmetros!$B$61+N14+Parâmetros!$B$78))),"")) | X14: =IF($B14="","",IF(ISNUMBER(R14),R14-M14-T14-U14-V14-W14,"")) | Y14: =IF($B14="","",IF(AND(ISNUMBER(R14),R14>0),X14/R14,"")) | Z14: =IF($B14="","",IF(AND(ISNUMBER(R14),ISNUMBER(G14)),R14-G14,"")) | AA14: =IF($B14="","",IF(NOT(ISNUMBER(R14)),"Percentuais ≥ 100%",IF(N(D14)=0,"Sem tempo",IF(J14=0,"Sem materiais",""))))
A15: 3.6 | B15: Peça em resina técnica direta indireta | C15: Clínica Geral | D15: 120 | E15: 0 | F15: 41.38 | J15: =IF($B15="","",SUMIFS(Itens!$E$2:$E$158,Itens!$A$2:$A$158,$B15)+N(F15)) | K15: =IF($B15="","",N(D15)/60*Parâmetros!$B$57) | L15: =IF($B15="","",N(D15)/60*Parâmetros!$B$60) | M15: =IF($B15="","",J15+N(E15)+K15+L15) | N15: =IF($B15="","",IF(H15="",Parâmetros!$B$62,H15)) | O15: =IF($B15="","",IF(I15="",Parâmetros!$B$63,I15)) | P15: =IF($B15="","",IF(1-(Parâmetros!$B$61+N15+Parâmetros!$B$78)-Parâmetros!$B$66-O15<=0,"ERRO",M15/(1-(Parâmetros!$B$61+N15+Parâmetros!$B$78)-Parâmetros!$B$66-O15))) | Q15: =IF($B15="","",IF((1-Parâmetros!$B$65)*(1-(Parâmetros!$B$61+N15+Parâmetros!$B$78))-O15<=0,"ERRO",(1-Parâmetros!$B$65)*M15/((1-Parâmetros!$B$65)*(1-(Parâmetros!$B$61+N15+Parâmetros!$B$78))-O15))) | R15: =IF($B15="","",IF(Parâmetros!$B$64=2,P15,Q15)) | S15: =IF($B15="","",IF(Parâmetros!$B$64=2,IF(1-(Parâmetros!$B$61+N15+Parâmetros!$B$78)-Parâmetros!$B$66<=0,"ERRO",M15/(1-(Parâmetros!$B$61+N15+Parâmetros!$B$78)-Parâmetros!$B$66)),IF((1-Parâmetros!$B$65)*(1-(Parâmetros!$B$61+N15+Parâmetros!$B$78))<=0,"ERRO",(1-Parâmetros!$B$65)*M15/((1-Parâmetros!$B$65)*(1-(Parâmetros!$B$61+N15+Parâmetros!$B$78)))))) | T15: =IF($B15="","",IF(ISNUMBER(R15),R15*Parâmetros!$B$61,"")) | U15: =IF($B15="","",IF(ISNUMBER(R15),R15*N15,"")) | V15: =IF($B15="","",IF(ISNUMBER(R15),R15*Parâmetros!$B$78,"")) | W15: =IF($B15="","",IF(ISNUMBER(R15),IF(Parâmetros!$B$64=2,R15*Parâmetros!$B$66,Parâmetros!$B$65*(R15-M15-R15*(Parâmetros!$B$61+N15+Parâmetros!$B$78))),"")) | X15: =IF($B15="","",IF(ISNUMBER(R15),R15-M15-T15-U15-V15-W15,"")) | Y15: =IF($B15="","",IF(AND(ISNUMBER(R15),R15>0),X15/R15,"")) | Z15: =IF($B15="","",IF(AND(ISNUMBER(R15),ISNUMBER(G15)),R15-G15,"")) | AA15: =IF($B15="","",IF(NOT(ISNUMBER(R15)),"Percentuais ≥ 100%",IF(N(D15)=0,"Sem tempo",IF(J15=0,"Sem materiais",""))))
A16: 4.0 | B16: Tratamento endodôntico unirradicular | C16: Clínica Geral | D16: 90 | E16: 0 | F16: 120 | J16: =IF($B16="","",SUMIFS(Itens!$E$2:$E$158,Itens!$A$2:$A$158,$B16)+N(F16)) | K16: =IF($B16="","",N(D16)/60*Parâmetros!$B$57) | L16: =IF($B16="","",N(D16)/60*Parâmetros!$B$60) | M16: =IF($B16="","",J16+N(E16)+K16+L16) | N16: =IF($B16="","",IF(H16="",Parâmetros!$B$62,H16)) | O16: =IF($B16="","",IF(I16="",Parâmetros!$B$63,I16)) | P16: =IF($B16="","",IF(1-(Parâmetros!$B$61+N16+Parâmetros!$B$78)-Parâmetros!$B$66-O16<=0,"ERRO",M16/(1-(Parâmetros!$B$61+N16+Parâmetros!$B$78)-Parâmetros!$B$66-O16))) | Q16: =IF($B16="","",IF((1-Parâmetros!$B$65)*(1-(Parâmetros!$B$61+N16+Parâmetros!$B$78))-O16<=0,"ERRO",(1-Parâmetros!$B$65)*M16/((1-Parâmetros!$B$65)*(1-(Parâmetros!$B$61+N16+Parâmetros!$B$78))-O16))) | R16: =IF($B16="","",IF(Parâmetros!$B$64=2,P16,Q16)) | S16: =IF($B16="","",IF(Parâmetros!$B$64=2,IF(1-(Parâmetros!$B$61+N16+Parâmetros!$B$78)-Parâmetros!$B$66<=0,"ERRO",M16/(1-(Parâmetros!$B$61+N16+Parâmetros!$B$78)-Parâmetros!$B$66)),IF((1-Parâmetros!$B$65)*(1-(Parâmetros!$B$61+N16+Parâmetros!$B$78))<=0,"ERRO",(1-Parâmetros!$B$65)*M16/((1-Parâmetros!$B$65)*(1-(Parâmetros!$B$61+N16+Parâmetros!$B$78)))))) | T16: =IF($B16="","",IF(ISNUMBER(R16),R16*Parâmetros!$B$61,"")) | U16: =IF($B16="","",IF(ISNUMBER(R16),R16*N16,"")) | V16: =IF($B16="","",IF(ISNUMBER(R16),R16*Parâmetros!$B$78,"")) | W16: =IF($B16="","",IF(ISNUMBER(R16),IF(Parâmetros!$B$64=2,R16*Parâmetros!$B$66,Parâmetros!$B$65*(R16-M16-R16*(Parâmetros!$B$61+N16+Parâmetros!$B$78))),"")) | X16: =IF($B16="","",IF(ISNUMBER(R16),R16-M16-T16-U16-V16-W16,"")) | Y16: =IF($B16="","",IF(AND(ISNUMBER(R16),R16>0),X16/R16,"")) | Z16: =IF($B16="","",IF(AND(ISNUMBER(R16),ISNUMBER(G16)),R16-G16,"")) | AA16: =IF($B16="","",IF(NOT(ISNUMBER(R16)),"Percentuais ≥ 100%",IF(N(D16)=0,"Sem tempo",IF(J16=0,"Sem materiais",""))))
A17: 4.1 | B17: Tratamento endodôntico birradicular | C17: Clínica Geral | D17: 90 | E17: 0 | F17: 130 | J17: =IF($B17="","",SUMIFS(Itens!$E$2:$E$158,Itens!$A$2:$A$158,$B17)+N(F17)) | K17: =IF($B17="","",N(D17)/60*Parâmetros!$B$57) | L17: =IF($B17="","",N(D17)/60*Parâmetros!$B$60) | M17: =IF($B17="","",J17+N(E17)+K17+L17) | N17: =IF($B17="","",IF(H17="",Parâmetros!$B$62,H17)) | O17: =IF($B17="","",IF(I17="",Parâmetros!$B$63,I17)) | P17: =IF($B17="","",IF(1-(Parâmetros!$B$61+N17+Parâmetros!$B$78)-Parâmetros!$B$66-O17<=0,"ERRO",M17/(1-(Parâmetros!$B$61+N17+Parâmetros!$B$78)-Parâmetros!$B$66-O17))) | Q17: =IF($B17="","",IF((1-Parâmetros!$B$65)*(1-(Parâmetros!$B$61+N17+Parâmetros!$B$78))-O17<=0,"ERRO",(1-Parâmetros!$B$65)*M17/((1-Parâmetros!$B$65)*(1-(Parâmetros!$B$61+N17+Parâmetros!$B$78))-O17))) | R17: =IF($B17="","",IF(Parâmetros!$B$64=2,P17,Q17)) | S17: =IF($B17="","",IF(Parâmetros!$B$64=2,IF(1-(Parâmetros!$B$61+N17+Parâmetros!$B$78)-Parâmetros!$B$66<=0,"ERRO",M17/(1-(Parâmetros!$B$61+N17+Parâmetros!$B$78)-Parâmetros!$B$66)),IF((1-Parâmetros!$B$65)*(1-(Parâmetros!$B$61+N17+Parâmetros!$B$78))<=0,"ERRO",(1-Parâmetros!$B$65)*M17/((1-Parâmetros!$B$65)*(1-(Parâmetros!$B$61+N17+Parâmetros!$B$78)))))) | T17: =IF($B17="","",IF(ISNUMBER(R17),R17*Parâmetros!$B$61,"")) | U17: =IF($B17="","",IF(ISNUMBER(R17),R17*N17,"")) | V17: =IF($B17="","",IF(ISNUMBER(R17),R17*Parâmetros!$B$78,"")) | W17: =IF($B17="","",IF(ISNUMBER(R17),IF(Parâmetros!$B$64=2,R17*Parâmetros!$B$66,Parâmetros!$B$65*(R17-M17-R17*(Parâmetros!$B$61+N17+Parâmetros!$B$78))),"")) | X17: =IF($B17="","",IF(ISNUMBER(R17),R17-M17-T17-U17-V17-W17,"")) | Y17: =IF($B17="","",IF(AND(ISNUMBER(R17),R17>0),X17/R17,"")) | Z17: =IF($B17="","",IF(AND(ISNUMBER(R17),ISNUMBER(G17)),R17-G17,"")) | AA17: =IF($B17="","",IF(NOT(ISNUMBER(R17)),"Percentuais ≥ 100%",IF(N(D17)=0,"Sem tempo",IF(J17=0,"Sem materiais",""))))
A18: 4.2 | B18: Tratamento endodôntico molar | C18: Clínica Geral | D18: 120 | E18: 0 | F18: 150 | J18: =IF($B18="","",SUMIFS(Itens!$E$2:$E$158,Itens!$A$2:$A$158,$B18)+N(F18)) | K18: =IF($B18="","",N(D18)/60*Parâmetros!$B$57) | L18: =IF($B18="","",N(D18)/60*Parâmetros!$B$60) | M18: =IF($B18="","",J18+N(E18)+K18+L18) | N18: =IF($B18="","",IF(H18="",Parâmetros!$B$62,H18)) | O18: =IF($B18="","",IF(I18="",Parâmetros!$B$63,I18)) | P18: =IF($B18="","",IF(1-(Parâmetros!$B$61+N18+Parâmetros!$B$78)-Parâmetros!$B$66-O18<=0,"ERRO",M18/(1-(Parâmetros!$B$61+N18+Parâmetros!$B$78)-Parâmetros!$B$66-O18))) | Q18: =IF($B18="","",IF((1-Parâmetros!$B$65)*(1-(Parâmetros!$B$61+N18+Parâmetros!$B$78))-O18<=0,"ERRO",(1-Parâmetros!$B$65)*M18/((1-Parâmetros!$B$65)*(1-(Parâmetros!$B$61+N18+Parâmetros!$B$78))-O18))) | R18: =IF($B18="","",IF(Parâmetros!$B$64=2,P18,Q18)) | S18: =IF($B18="","",IF(Parâmetros!$B$64=2,IF(1-(Parâmetros!$B$61+N18+Parâmetros!$B$78)-Parâmetros!$B$66<=0,"ERRO",M18/(1-(Parâmetros!$B$61+N18+Parâmetros!$B$78)-Parâmetros!$B$66)),IF((1-Parâmetros!$B$65)*(1-(Parâmetros!$B$61+N18+Parâmetros!$B$78))<=0,"ERRO",(1-Parâmetros!$B$65)*M18/((1-Parâmetros!$B$65)*(1-(Parâmetros!$B$61+N18+Parâmetros!$B$78)))))) | T18: =IF($B18="","",IF(ISNUMBER(R18),R18*Parâmetros!$B$61,"")) | U18: =IF($B18="","",IF(ISNUMBER(R18),R18*N18,"")) | V18: =IF($B18="","",IF(ISNUMBER(R18),R18*Parâmetros!$B$78,"")) | W18: =IF($B18="","",IF(ISNUMBER(R18),IF(Parâmetros!$B$64=2,R18*Parâmetros!$B$66,Parâmetros!$B$65*(R18-M18-R18*(Parâmetros!$B$61+N18+Parâmetros!$B$78))),"")) | X18: =IF($B18="","",IF(ISNUMBER(R18),R18-M18-T18-U18-V18-W18,"")) | Y18: =IF($B18="","",IF(AND(ISNUMBER(R18),R18>0),X18/R18,"")) | Z18: =IF($B18="","",IF(AND(ISNUMBER(R18),ISNUMBER(G18)),R18-G18,"")) | AA18: =IF($B18="","",IF(NOT(ISNUMBER(R18)),"Percentuais ≥ 100%",IF(N(D18)=0,"Sem tempo",IF(J18=0,"Sem materiais",""))))
A19: 4.3 | B19: Retratamento endodôntico unirradicular | C19: Clínica Geral | D19: 90 | E19: 0 | F19: 130 | J19: =IF($B19="","",SUMIFS(Itens!$E$2:$E$158,Itens!$A$2:$A$158,$B19)+N(F19)) | K19: =IF($B19="","",N(D19)/60*Parâmetros!$B$57) | L19: =IF($B19="","",N(D19)/60*Parâmetros!$B$60) | M19: =IF($B19="","",J19+N(E19)+K19+L19) | N19: =IF($B19="","",IF(H19="",Parâmetros!$B$62,H19)) | O19: =IF($B19="","",IF(I19="",Parâmetros!$B$63,I19)) | P19: =IF($B19="","",IF(1-(Parâmetros!$B$61+N19+Parâmetros!$B$78)-Parâmetros!$B$66-O19<=0,"ERRO",M19/(1-(Parâmetros!$B$61+N19+Parâmetros!$B$78)-Parâmetros!$B$66-O19))) | Q19: =IF($B19="","",IF((1-Parâmetros!$B$65)*(1-(Parâmetros!$B$61+N19+Parâmetros!$B$78))-O19<=0,"ERRO",(1-Parâmetros!$B$65)*M19/((1-Parâmetros!$B$65)*(1-(Parâmetros!$B$61+N19+Parâmetros!$B$78))-O19))) | R19: =IF($B19="","",IF(Parâmetros!$B$64=2,P19,Q19)) | S19: =IF($B19="","",IF(Parâmetros!$B$64=2,IF(1-(Parâmetros!$B$61+N19+Parâmetros!$B$78)-Parâmetros!$B$66<=0,"ERRO",M19/(1-(Parâmetros!$B$61+N19+Parâmetros!$B$78)-Parâmetros!$B$66)),IF((1-Parâmetros!$B$65)*(1-(Parâmetros!$B$61+N19+Parâmetros!$B$78))<=0,"ERRO",(1-Parâmetros!$B$65)*M19/((1-Parâmetros!$B$65)*(1-(Parâmetros!$B$61+N19+Parâmetros!$B$78)))))) | T19: =IF($B19="","",IF(ISNUMBER(R19),R19*Parâmetros!$B$61,"")) | U19: =IF($B19="","",IF(ISNUMBER(R19),R19*N19,"")) | V19: =IF($B19="","",IF(ISNUMBER(R19),R19*Parâmetros!$B$78,"")) | W19: =IF($B19="","",IF(ISNUMBER(R19),IF(Parâmetros!$B$64=2,R19*Parâmetros!$B$66,Parâmetros!$B$65*(R19-M19-R19*(Parâmetros!$B$61+N19+Parâmetros!$B$78))),"")) | X19: =IF($B19="","",IF(ISNUMBER(R19),R19-M19-T19-U19-V19-W19,"")) | Y19: =IF($B19="","",IF(AND(ISNUMBER(R19),R19>0),X19/R19,"")) | Z19: =IF($B19="","",IF(AND(ISNUMBER(R19),ISNUMBER(G19)),R19-G19,"")) | AA19: =IF($B19="","",IF(NOT(ISNUMBER(R19)),"Percentuais ≥ 100%",IF(N(D19)=0,"Sem tempo",IF(J19=0,"Sem materiais",""))))
A20: 4.4 | B20: Retratamento endodôntico birradicular | C20: Clínica Geral | D20: 90 | E20: 0 | F20: 140 | J20: =IF($B20="","",SUMIFS(Itens!$E$2:$E$158,Itens!$A$2:$A$158,$B20)+N(F20)) | K20: =IF($B20="","",N(D20)/60*Parâmetros!$B$57) | L20: =IF($B20="","",N(D20)/60*Parâmetros!$B$60) | M20: =IF($B20="","",J20+N(E20)+K20+L20) | N20: =IF($B20="","",IF(H20="",Parâmetros!$B$62,H20)) | O20: =IF($B20="","",IF(I20="",Parâmetros!$B$63,I20)) | P20: =IF($B20="","",IF(1-(Parâmetros!$B$61+N20+Parâmetros!$B$78)-Parâmetros!$B$66-O20<=0,"ERRO",M20/(1-(Parâmetros!$B$61+N20+Parâmetros!$B$78)-Parâmetros!$B$66-O20))) | Q20: =IF($B20="","",IF((1-Parâmetros!$B$65)*(1-(Parâmetros!$B$61+N20+Parâmetros!$B$78))-O20<=0,"ERRO",(1-Parâmetros!$B$65)*M20/((1-Parâmetros!$B$65)*(1-(Parâmetros!$B$61+N20+Parâmetros!$B$78))-O20))) | R20: =IF($B20="","",IF(Parâmetros!$B$64=2,P20,Q20)) | S20: =IF($B20="","",IF(Parâmetros!$B$64=2,IF(1-(Parâmetros!$B$61+N20+Parâmetros!$B$78)-Parâmetros!$B$66<=0,"ERRO",M20/(1-(Parâmetros!$B$61+N20+Parâmetros!$B$78)-Parâmetros!$B$66)),IF((1-Parâmetros!$B$65)*(1-(Parâmetros!$B$61+N20+Parâmetros!$B$78))<=0,"ERRO",(1-Parâmetros!$B$65)*M20/((1-Parâmetros!$B$65)*(1-(Parâmetros!$B$61+N20+Parâmetros!$B$78)))))) | T20: =IF($B20="","",IF(ISNUMBER(R20),R20*Parâmetros!$B$61,"")) | U20: =IF($B20="","",IF(ISNUMBER(R20),R20*N20,"")) | V20: =IF($B20="","",IF(ISNUMBER(R20),R20*Parâmetros!$B$78,"")) | W20: =IF($B20="","",IF(ISNUMBER(R20),IF(Parâmetros!$B$64=2,R20*Parâmetros!$B$66,Parâmetros!$B$65*(R20-M20-R20*(Parâmetros!$B$61+N20+Parâmetros!$B$78))),"")) | X20: =IF($B20="","",IF(ISNUMBER(R20),R20-M20-T20-U20-V20-W20,"")) | Y20: =IF($B20="","",IF(AND(ISNUMBER(R20),R20>0),X20/R20,"")) | Z20: =IF($B20="","",IF(AND(ISNUMBER(R20),ISNUMBER(G20)),R20-G20,"")) | AA20: =IF($B20="","",IF(NOT(ISNUMBER(R20)),"Percentuais ≥ 100%",IF(N(D20)=0,"Sem tempo",IF(J20=0,"Sem materiais",""))))
... A29: 6.1 | B29: Raspagem periodontal a retalho | C29: Clínica Geral | D29: 90 | E29: 0 | F29: 60 | J29: =IF($B29="","",SUMIFS(Itens!$E$2:$E$158,Itens!$A$2:$A$158,$B29)+N(F29)) | K29: =IF($B29="","",N(D29)/60*Parâmetros!$B$57) | L29: =IF($B29="","",N(D29)/60*Parâmetros!$B$60) | M29: =IF($B29="","",J29+N(E29)+K29+L29) | N29: =IF($B29="","",IF(H29="",Parâmetros!$B$62,H29)) | O29: =IF($B29="","",IF(I29="",Parâmetros!$B$63,I29)) | P29: =IF($B29="","",IF(1-(Parâmetros!$B$61+N29+Parâmetros!$B$78)-Parâmetros!$B$66-O29<=0,"ERRO",M29/(1-(Parâmetros!$B$61+N29+Parâmetros!$B$78)-Parâmetros!$B$66-O29))) | Q29: =IF($B29="","",IF((1-Parâmetros!$B$65)*(1-(Parâmetros!$B$61+N29+Parâmetros!$B$78))-O29<=0,"ERRO",(1-Parâmetros!$B$65)*M29/((1-Parâmetros!$B$65)*(1-(Parâmetros!$B$61+N29+Parâmetros!$B$78))-O29))) | R29: =IF($B29="","",IF(Parâmetros!$B$64=2,P29,Q29)) | S29: =IF($B29="","",IF(Parâmetros!$B$64=2,IF(1-(Parâmetros!$B$61+N29+Parâmetros!$B$78)-Parâmetros!$B$66<=0,"ERRO",M29/(1-(Parâmetros!$B$61+N29+Parâmetros!$B$78)-Parâmetros!$B$66)),IF((1-Parâmetros!$B$65)*(1-(Parâmetros!$B$61+N29+Parâmetros!$B$78))<=0,"ERRO",(1-Parâmetros!$B$65)*M29/((1-Parâmetros!$B$65)*(1-(Parâmetros!$B$61+N29+Parâmetros!$B$78)))))) | T29: =IF($B29="","",IF(ISNUMBER(R29),R29*Parâmetros!$B$61,"")) | U29: =IF($B29="","",IF(ISNUMBER(R29),R29*N29,"")) | V29: =IF($B29="","",IF(ISNUMBER(R29),R29*Parâmetros!$B$78,"")) | W29: =IF($B29="","",IF(ISNUMBER(R29),IF(Parâmetros!$B$64=2,R29*Parâmetros!$B$66,Parâmetros!$B$65*(R29-M29-R29*(Parâmetros!$B$61+N29+Parâmetros!$B$78))),"")) | X29: =IF($B29="","",IF(ISNUMBER(R29),R29-M29-T29-U29-V29-W29,"")) | Y29: =IF($B29="","",IF(AND(ISNUMBER(R29),R29>0),X29/R29,"")) | Z29: =IF($B29="","",IF(AND(ISNUMBER(R29),ISNUMBER(G29)),R29-G29,"")) | AA29: =IF($B29="","",IF(NOT(ISNUMBER(R29)),"Percentuais ≥ 100%",IF(N(D29)=0,"Sem tempo",IF(J29=0,"Sem materiais",""))))
A30: 7.0 | B30: Implante unitário | C30: Implante | D30: 0 | E30: 0 | F30: 0 | I30: 0.2 | J30: =IF($B30="","",SUMIFS(Itens!$E$2:$E$158,Itens!$A$2:$A$158,$B30)+N(F30)) | K30: =IF($B30="","",N(D30)/60*Parâmetros!$B$57) | L30: =IF($B30="","",N(D30)/60*Parâmetros!$B$60) | M30: =IF($B30="","",J30+N(E30)+K30+L30) | N30: =IF($B30="","",IF(H30="",Parâmetros!$B$62,H30)) | O30: =IF($B30="","",IF(I30="",Parâmetros!$B$63,I30)) | P30: =IF($B30="","",IF(1-(Parâmetros!$B$61+N30+Parâmetros!$B$78)-Parâmetros!$B$66-O30<=0,"ERRO",M30/(1-(Parâmetros!$B$61+N30+Parâmetros!$B$78)-Parâmetros!$B$66-O30))) | Q30: =IF($B30="","",IF((1-Parâmetros!$B$65)*(1-(Parâmetros!$B$61+N30+Parâmetros!$B$78))-O30<=0,"ERRO",(1-Parâmetros!$B$65)*M30/((1-Parâmetros!$B$65)*(1-(Parâmetros!$B$61+N30+Parâmetros!$B$78))-O30))) | R30: =IF($B30="","",IF(Parâmetros!$B$64=2,P30,Q30)) | S30: =IF($B30="","",IF(Parâmetros!$B$64=2,IF(1-(Parâmetros!$B$61+N30+Parâmetros!$B$78)-Parâmetros!$B$66<=0,"ERRO",M30/(1-(Parâmetros!$B$61+N30+Parâmetros!$B$78)-Parâmetros!$B$66)),IF((1-Parâmetros!$B$65)*(1-(Parâmetros!$B$61+N30+Parâmetros!$B$78))<=0,"ERRO",(1-Parâmetros!$B$65)*M30/((1-Parâmetros!$B$65)*(1-(Parâmetros!$B$61+N30+Parâmetros!$B$78)))))) | T30: =IF($B30="","",IF(ISNUMBER(R30),R30*Parâmetros!$B$61,"")) | U30: =IF($B30="","",IF(ISNUMBER(R30),R30*N30,"")) | V30: =IF($B30="","",IF(ISNUMBER(R30),R30*Parâmetros!$B$78,"")) | W30: =IF($B30="","",IF(ISNUMBER(R30),IF(Parâmetros!$B$64=2,R30*Parâmetros!$B$66,Parâmetros!$B$65*(R30-M30-R30*(Parâmetros!$B$61+N30+Parâmetros!$B$78))),"")) | X30: =IF($B30="","",IF(ISNUMBER(R30),R30-M30-T30-U30-V30-W30,"")) | Y30: =IF($B30="","",IF(AND(ISNUMBER(R30),R30>0),X30/R30,"")) | Z30: =IF($B30="","",IF(AND(ISNUMBER(R30),ISNUMBER(G30)),R30-G30,"")) | AA30: =IF($B30="","",IF(NOT(ISNUMBER(R30)),"Percentuais ≥ 100%",IF(N(D30)=0,"Sem tempo",IF(J30=0,"Sem materiais",""))))
A31: 7.1 | B31: Implante unitário com enxerto ósseo | C31: Implante | D31: 0 | E31: 0 | F31: 0 | I31: 0.2 | J31: =IF($B31="","",SUMIFS(Itens!$E$2:$E$158,Itens!$A$2:$A$158,$B31)+N(F31)) | K31: =IF($B31="","",N(D31)/60*Parâmetros!$B$57) | L31: =IF($B31="","",N(D31)/60*Parâmetros!$B$60) | M31: =IF($B31="","",J31+N(E31)+K31+L31) | N31: =IF($B31="","",IF(H31="",Parâmetros!$B$62,H31)) | O31: =IF($B31="","",IF(I31="",Parâmetros!$B$63,I31)) | P31: =IF($B31="","",IF(1-(Parâmetros!$B$61+N31+Parâmetros!$B$78)-Parâmetros!$B$66-O31<=0,"ERRO",M31/(1-(Parâmetros!$B$61+N31+Parâmetros!$B$78)-Parâmetros!$B$66-O31))) | Q31: =IF($B31="","",IF((1-Parâmetros!$B$65)*(1-(Parâmetros!$B$61+N31+Parâmetros!$B$78))-O31<=0,"ERRO",(1-Parâmetros!$B$65)*M31/((1-Parâmetros!$B$65)*(1-(Parâmetros!$B$61+N31+Parâmetros!$B$78))-O31))) | R31: =IF($B31="","",IF(Parâmetros!$B$64=2,P31,Q31)) | S31: =IF($B31="","",IF(Parâmetros!$B$64=2,IF(1-(Parâmetros!$B$61+N31+Parâmetros!$B$78)-Parâmetros!$B$66<=0,"ERRO",M31/(1-(Parâmetros!$B$61+N31+Parâmetros!$B$78)-Parâmetros!$B$66)),IF((1-Parâmetros!$B$65)*(1-(Parâmetros!$B$61+N31+Parâmetros!$B$78))<=0,"ERRO",(1-Parâmetros!$B$65)*M31/((1-Parâmetros!$B$65)*(1-(Parâmetros!$B$61+N31+Parâmetros!$B$78)))))) | T31: =IF($B31="","",IF(ISNUMBER(R31),R31*Parâmetros!$B$61,"")) | U31: =IF($B31="","",IF(ISNUMBER(R31),R31*N31,"")) | V31: =IF($B31="","",IF(ISNUMBER(R31),R31*Parâmetros!$B$78,"")) | W31: =IF($B31="","",IF(ISNUMBER(R31),IF(Parâmetros!$B$64=2,R31*Parâmetros!$B$66,Parâmetros!$B$65*(R31-M31-R31*(Parâmetros!$B$61+N31+Parâmetros!$B$78))),"")) | X31: =IF($B31="","",IF(ISNUMBER(R31),R31-M31-T31-U31-V31-W31,"")) | Y31: =IF($B31="","",IF(AND(ISNUMBER(R31),R31>0),X31/R31,"")) | Z31: =IF($B31="","",IF(AND(ISNUMBER(R31),ISNUMBER(G31)),R31-G31,"")) | AA31: =IF($B31="","",IF(NOT(ISNUMBER(R31)),"Percentuais ≥ 100%",IF(N(D31)=0,"Sem tempo",IF(J31=0,"Sem materiais",""))))
A32: 8.0 | B32: Manutenção ortodontica convencional nac | C32: Ortodontia | D32: 30 | E32: 0 | F32: 7 | G32: 120 | J32: =IF($B32="","",SUMIFS(Itens!$E$2:$E$158,Itens!$A$2:$A$158,$B32)+N(F32)) | K32: =IF($B32="","",N(D32)/60*Parâmetros!$B$57) | L32: =IF($B32="","",N(D32)/60*Parâmetros!$B$60) | M32: =IF($B32="","",J32+N(E32)+K32+L32) | N32: =IF($B32="","",IF(H32="",Parâmetros!$B$62,H32)) | O32: =IF($B32="","",IF(I32="",Parâmetros!$B$63,I32)) | P32: =IF($B32="","",IF(1-(Parâmetros!$B$61+N32+Parâmetros!$B$78)-Parâmetros!$B$66-O32<=0,"ERRO",M32/(1-(Parâmetros!$B$61+N32+Parâmetros!$B$78)-Parâmetros!$B$66-O32))) | Q32: =IF($B32="","",IF((1-Parâmetros!$B$65)*(1-(Parâmetros!$B$61+N32+Parâmetros!$B$78))-O32<=0,"ERRO",(1-Parâmetros!$B$65)*M32/((1-Parâmetros!$B$65)*(1-(Parâmetros!$B$61+N32+Parâmetros!$B$78))-O32))) | R32: =IF($B32="","",IF(Parâmetros!$B$64=2,P32,Q32)) | S32: =IF($B32="","",IF(Parâmetros!$B$64=2,IF(1-(Parâmetros!$B$61+N32+Parâmetros!$B$78)-Parâmetros!$B$66<=0,"ERRO",M32/(1-(Parâmetros!$B$61+N32+Parâmetros!$B$78)-Parâmetros!$B$66)),IF((1-Parâmetros!$B$65)*(1-(Parâmetros!$B$61+N32+Parâmetros!$B$78))<=0,"ERRO",(1-Parâmetros!$B$65)*M32/((1-Parâmetros!$B$65)*(1-(Parâmetros!$B$61+N32+Parâmetros!$B$78)))))) | T32: =IF($B32="","",IF(ISNUMBER(R32),R32*Parâmetros!$B$61,"")) | U32: =IF($B32="","",IF(ISNUMBER(R32),R32*N32,"")) | V32: =IF($B32="","",IF(ISNUMBER(R32),R32*Parâmetros!$B$78,"")) | W32: =IF($B32="","",IF(ISNUMBER(R32),IF(Parâmetros!$B$64=2,R32*Parâmetros!$B$66,Parâmetros!$B$65*(R32-M32-R32*(Parâmetros!$B$61+N32+Parâmetros!$B$78))),"")) | X32: =IF($B32="","",IF(ISNUMBER(R32),R32-M32-T32-U32-V32-W32,"")) | Y32: =IF($B32="","",IF(AND(ISNUMBER(R32),R32>0),X32/R32,"")) | Z32: =IF($B32="","",IF(AND(ISNUMBER(R32),ISNUMBER(G32)),R32-G32,"")) | AA32: =IF($B32="","",IF(NOT(ISNUMBER(R32)),"Percentuais ≥ 100%",IF(N(D32)=0,"Sem tempo",IF(J32=0,"Sem materiais",""))))
A33: 8.1 | B33: Manutenção ortodontica convencional imp | C33: Ortodontia | D33: 30 | E33: 0 | F33: 7.5 | G33: 120 | J33: =IF($B33="","",SUMIFS(Itens!$E$2:$E$158,Itens!$A$2:$A$158,$B33)+N(F33)) | K33: =IF($B33="","",N(D33)/60*Parâmetros!$B$57) | L33: =IF($B33="","",N(D33)/60*Parâmetros!$B$60) | M33: =IF($B33="","",J33+N(E33)+K33+L33) | N33: =IF($B33="","",IF(H33="",Parâmetros!$B$62,H33)) | O33: =IF($B33="","",IF(I33="",Parâmetros!$B$63,I33)) | P33: =IF($B33="","",IF(1-(Parâmetros!$B$61+N33+Parâmetros!$B$78)-Parâmetros!$B$66-O33<=0,"ERRO",M33/(1-(Parâmetros!$B$61+N33+Parâmetros!$B$78)-Parâmetros!$B$66-O33))) | Q33: =IF($B33="","",IF((1-Parâmetros!$B$65)*(1-(Parâmetros!$B$61+N33+Parâmetros!$B$78))-O33<=0,"ERRO",(1-Parâmetros!$B$65)*M33/((1-Parâmetros!$B$65)*(1-(Parâmetros!$B$61+N33+Parâmetros!$B$78))-O33))) | R33: =IF($B33="","",IF(Parâmetros!$B$64=2,P33,Q33)) | S33: =IF($B33="","",IF(Parâmetros!$B$64=2,IF(1-(Parâmetros!$B$61+N33+Parâmetros!$B$78)-Parâmetros!$B$66<=0,"ERRO",M33/(1-(Parâmetros!$B$61+N33+Parâmetros!$B$78)-Parâmetros!$B$66)),IF((1-Parâmetros!$B$65)*(1-(Parâmetros!$B$61+N33+Parâmetros!$B$78))<=0,"ERRO",(1-Parâmetros!$B$65)*M33/((1-Parâmetros!$B$65)*(1-(Parâmetros!$B$61+N33+Parâmetros!$B$78)))))) | T33: =IF($B33="","",IF(ISNUMBER(R33),R33*Parâmetros!$B$61,"")) | U33: =IF($B33="","",IF(ISNUMBER(R33),R33*N33,"")) | V33: =IF($B33="","",IF(ISNUMBER(R33),R33*Parâmetros!$B$78,"")) | W33: =IF($B33="","",IF(ISNUMBER(R33),IF(Parâmetros!$B$64=2,R33*Parâmetros!$B$66,Parâmetros!$B$65*(R33-M33-R33*(Parâmetros!$B$61+N33+Parâmetros!$B$78))),"")) | X33: =IF($B33="","",IF(ISNUMBER(R33),R33-M33-T33-U33-V33-W33,"")) | Y33: =IF($B33="","",IF(AND(ISNUMBER(R33),R33>0),X33/R33,"")) | Z33: =IF($B33="","",IF(AND(ISNUMBER(R33),ISNUMBER(G33)),R33-G33,"")) | AA33: =IF($B33="","",IF(NOT(ISNUMBER(R33)),"Percentuais ≥ 100%",IF(N(D33)=0,"Sem tempo",IF(J33=0,"Sem materiais",""))))
A34: 8.2 | B34: Manutenção ortodontica autoligado metálico | C34: Ortodontia | D34: 30 | E34: 0 | F34: 20 | G34: 220 | J34: =IF($B34="","",SUMIFS(Itens!$E$2:$E$158,Itens!$A$2:$A$158,$B34)+N(F34)) | K34: =IF($B34="","",N(D34)/60*Parâmetros!$B$57) | L34: =IF($B34="","",N(D34)/60*Parâmetros!$B$60) | M34: =IF($B34="","",J34+N(E34)+K34+L34) | N34: =IF($B34="","",IF(H34="",Parâmetros!$B$62,H34)) | O34: =IF($B34="","",IF(I34="",Parâmetros!$B$63,I34)) | P34: =IF($B34="","",IF(1-(Parâmetros!$B$61+N34+Parâmetros!$B$78)-Parâmetros!$B$66-O34<=0,"ERRO",M34/(1-(Parâmetros!$B$61+N34+Parâmetros!$B$78)-Parâmetros!$B$66-O34))) | Q34: =IF($B34="","",IF((1-Parâmetros!$B$65)*(1-(Parâmetros!$B$61+N34+Parâmetros!$B$78))-O34<=0,"ERRO",(1-Parâmetros!$B$65)*M34/((1-Parâmetros!$B$65)*(1-(Parâmetros!$B$61+N34+Parâmetros!$B$78))-O34))) | R34: =IF($B34="","",IF(Parâmetros!$B$64=2,P34,Q34)) | S34: =IF($B34="","",IF(Parâmetros!$B$64=2,IF(1-(Parâmetros!$B$61+N34+Parâmetros!$B$78)-Parâmetros!$B$66<=0,"ERRO",M34/(1-(Parâmetros!$B$61+N34+Parâmetros!$B$78)-Parâmetros!$B$66)),IF((1-Parâmetros!$B$65)*(1-(Parâmetros!$B$61+N34+Parâmetros!$B$78))<=0,"ERRO",(1-Parâmetros!$B$65)*M34/((1-Parâmetros!$B$65)*(1-(Parâmetros!$B$61+N34+Parâmetros!$B$78)))))) | T34: =IF($B34="","",IF(ISNUMBER(R34),R34*Parâmetros!$B$61,"")) | U34: =IF($B34="","",IF(ISNUMBER(R34),R34*N34,"")) | V34: =IF($B34="","",IF(ISNUMBER(R34),R34*Parâmetros!$B$78,"")) | W34: =IF($B34="","",IF(ISNUMBER(R34),IF(Parâmetros!$B$64=2,R34*Parâmetros!$B$66,Parâmetros!$B$65*(R34-M34-R34*(Parâmetros!$B$61+N34+Parâmetros!$B$78))),"")) | X34: =IF($B34="","",IF(ISNUMBER(R34),R34-M34-T34-U34-V34-W34,"")) | Y34: =IF($B34="","",IF(AND(ISNUMBER(R34),R34>0),X34/R34,"")) | Z34: =IF($B34="","",IF(AND(ISNUMBER(R34),ISNUMBER(G34)),R34-G34,"")) | AA34: =IF($B34="","",IF(NOT(ISNUMBER(R34)),"Percentuais ≥ 100%",IF(N(D34)=0,"Sem tempo",IF(J34=0,"Sem materiais",""))))
A35: 8.3 | B35: Manutenção ortodontica safira | C35: Ortodontia | D35: 30 | E35: 0 | F35: 60 | G35: 260 | J35: =IF($B35="","",SUMIFS(Itens!$E$2:$E$158,Itens!$A$2:$A$158,$B35)+N(F35)) | K35: =IF($B35="","",N(D35)/60*Parâmetros!$B$57) | L35: =IF($B35="","",N(D35)/60*Parâmetros!$B$60) | M35: =IF($B35="","",J35+N(E35)+K35+L35) | N35: =IF($B35="","",IF(H35="",Parâmetros!$B$62,H35)) | O35: =IF($B35="","",IF(I35="",Parâmetros!$B$63,I35)) | P35: =IF($B35="","",IF(1-(Parâmetros!$B$61+N35+Parâmetros!$B$78)-Parâmetros!$B$66-O35<=0,"ERRO",M35/(1-(Parâmetros!$B$61+N35+Parâmetros!$B$78)-Parâmetros!$B$66-O35))) | Q35: =IF($B35="","",IF((1-Parâmetros!$B$65)*(1-(Parâmetros!$B$61+N35+Parâmetros!$B$78))-O35<=0,"ERRO",(1-Parâmetros!$B$65)*M35/((1-Parâmetros!$B$65)*(1-(Parâmetros!$B$61+N35+Parâmetros!$B$78))-O35))) | R35: =IF($B35="","",IF(Parâmetros!$B$64=2,P35,Q35)) | S35: =IF($B35="","",IF(Parâmetros!$B$64=2,IF(1-(Parâmetros!$B$61+N35+Parâmetros!$B$78)-Parâmetros!$B$66<=0,"ERRO",M35/(1-(Parâmetros!$B$61+N35+Parâmetros!$B$78)-Parâmetros!$B$66)),IF((1-Parâmetros!$B$65)*(1-(Parâmetros!$B$61+N35+Parâmetros!$B$78))<=0,"ERRO",(1-Parâmetros!$B$65)*M35/((1-Parâmetros!$B$65)*(1-(Parâmetros!$B$61+N35+Parâmetros!$B$78)))))) | T35: =IF($B35="","",IF(ISNUMBER(R35),R35*Parâmetros!$B$61,"")) | U35: =IF($B35="","",IF(ISNUMBER(R35),R35*N35,"")) | V35: =IF($B35="","",IF(ISNUMBER(R35),R35*Parâmetros!$B$78,"")) | W35: =IF($B35="","",IF(ISNUMBER(R35),IF(Parâmetros!$B$64=2,R35*Parâmetros!$B$66,Parâmetros!$B$65*(R35-M35-R35*(Parâmetros!$B$61+N35+Parâmetros!$B$78))),"")) | X35: =IF($B35="","",IF(ISNUMBER(R35),R35-M35-T35-U35-V35-W35,"")) | Y35: =IF($B35="","",IF(AND(ISNUMBER(R35),R35>0),X35/R35,"")) | Z35: =IF($B35="","",IF(AND(ISNUMBER(R35),ISNUMBER(G35)),R35-G35,"")) | AA35: =IF($B35="","",IF(NOT(ISNUMBER(R35)),"Percentuais ≥ 100%",IF(N(D35)=0,"Sem tempo",IF(J35=0,"Sem materiais",""))))
A36: 9.0 | B36: Instalação aparelho metálico conv nacional | C36: Ortodontia | D36: 90 | E36: 0 | F36: 36.78 | G36: 450 | J36: =IF($B36="","",SUMIFS(Itens!$E$2:$E$158,Itens!$A$2:$A$158,$B36)+N(F36)) | K36: =IF($B36="","",N(D36)/60*Parâmetros!$B$57) | L36: =IF($B36="","",N(D36)/60*Parâmetros!$B$60) | M36: =IF($B36="","",J36+N(E36)+K36+L36) | N36: =IF($B36="","",IF(H36="",Parâmetros!$B$62,H36)) | O36: =IF($B36="","",IF(I36="",Parâmetros!$B$63,I36)) | P36: =IF($B36="","",IF(1-(Parâmetros!$B$61+N36+Parâmetros!$B$78)-Parâmetros!$B$66-O36<=0,"ERRO",M36/(1-(Parâmetros!$B$61+N36+Parâmetros!$B$78)-Parâmetros!$B$66-O36))) | Q36: =IF($B36="","",IF((1-Parâmetros!$B$65)*(1-(Parâmetros!$B$61+N36+Parâmetros!$B$78))-O36<=0,"ERRO",(1-Parâmetros!$B$65)*M36/((1-Parâmetros!$B$65)*(1-(Parâmetros!$B$61+N36+Parâmetros!$B$78))-O36))) | R36: =IF($B36="","",IF(Parâmetros!$B$64=2,P36,Q36)) | S36: =IF($B36="","",IF(Parâmetros!$B$64=2,IF(1-(Parâmetros!$B$61+N36+Parâmetros!$B$78)-Parâmetros!$B$66<=0,"ERRO",M36/(1-(Parâmetros!$B$61+N36+Parâmetros!$B$78)-Parâmetros!$B$66)),IF((1-Parâmetros!$B$65)*(1-(Parâmetros!$B$61+N36+Parâmetros!$B$78))<=0,"ERRO",(1-Parâmetros!$B$65)*M36/((1-Parâmetros!$B$65)*(1-(Parâmetros!$B$61+N36+Parâmetros!$B$78)))))) | T36: =IF($B36="","",IF(ISNUMBER(R36),R36*Parâmetros!$B$61,"")) | U36: =IF($B36="","",IF(ISNUMBER(R36),R36*N36,"")) | V36: =IF($B36="","",IF(ISNUMBER(R36),R36*Parâmetros!$B$78,"")) | W36: =IF($B36="","",IF(ISNUMBER(R36),IF(Parâmetros!$B$64=2,R36*Parâmetros!$B$66,Parâmetros!$B$65*(R36-M36-R36*(Parâmetros!$B$61+N36+Parâmetros!$B$78))),"")) | X36: =IF($B36="","",IF(ISNUMBER(R36),R36-M36-T36-U36-V36-W36,"")) | Y36: =IF($B36="","",IF(AND(ISNUMBER(R36),R36>0),X36/R36,"")) | Z36: =IF($B36="","",IF(AND(ISNUMBER(R36),ISNUMBER(G36)),R36-G36,"")) | AA36: =IF($B36="","",IF(NOT(ISNUMBER(R36)),"Percentuais ≥ 100%",IF(N(D36)=0,"Sem tempo",IF(J36=0,"Sem materiais",""))))
